<?xml version="1.0"?>
<robot name="bluecrescent">

      <material name="skin">
        <color rgba="1 0.6 0.4 1"/>
      </material>
      <material name="blue">
        <color rgba="0 0 1 1"/>
      </material>
      <material name="white">
        <color rgba="1 1 1 1"/>
      </material>
      <material name="gray">
        <color rgba="0.5 0.5 0.5 1"/>
      </material>
      <material name="green">
        <color rgba="0 1 0 1"/>
      </material>
      <material name="red">
        <color rgba="1 0 0 1"/>
      </material>


        <link name="head">
          <visual>
            <geometry>
              <box size="0.06 0.06 0.06"/>
            </geometry>
            <material name="skin"/>
          </visual>
         <collision>
            <geometry>
              <box size="0.06 0.06 0.06"/>
            </geometry>
         </collision>
      
        </link>
        <joint name="roll_head" type="revolute">
      	<limit effort="1000.0" lower="-0.5" upper="0.5" velocity="0.5"/>
        	<parent link="neckjoint"/>
       	<child link="head"/>
        	<origin rpy="0 0 0" xyz="0 0 0.045"/>
        </joint>
        <link name="neckjoint">
        </link>
        <joint name="yaw_head" type="revolute">
      	<limit effort="1000.0" lower="-0.5" upper="0.5" velocity="0.5"/>
        	<parent link="neck"/>
      	<child link="neckjoint"/>
      	<axis xyz="0 0 1"/>
        	<origin rpy="0 0 0" xyz="0 0 0"/>
        </joint>
        <link name="neck">
          <visual>
            <geometry>
              <cylinder length="0.03" radius="0.01"/>
            </geometry>
            <material name="blue"/>
          </visual>
          <collision>
            <geometry>
              <cylinder length="0.03" radius="0.01"/>
            </geometry>
          </collision>
        </link>
        <joint name="neck_body" type="fixed">
        	<parent link="base_link"/>
       	<child link="neck"/>
      	<origin xyz="0 0 0.085"/>
        </joint>

  <link name="base_link">
    <visual>
      <geometry>
        <box size="0.06 0.03 0.14"/>
      </geometry>
      <material name="blue"/>
    </visual>
    <collision>
      <geometry>
        <box size="0.06 0.03 0.14"/>
      </geometry>
    </collision>
  </link>

    <joint name="arm_shoulder_right_roll" type="revolute">
  	<limit effort="1000.0" lower="-3.14" upper="3.14" velocity="0.5"/>
    	<parent link="base_link"/>
   	<child link="arm_shoulder_right_joint"/>
    	<origin rpy="0 -0.1 0" xyz="0.045 0 0.06"/>
    </joint>
    <link name="arm_shoulder_right_joint">
    </link>
    <joint name="arm_shoulder_right_pitch" type="revolute">
  	<limit effort="1000.0" lower="-3.14" upper="3.14" velocity="0.5"/>
    	<parent link="arm_shoulder_right_joint"/>
   	<child link="arm_upper_right"/>
  	<axis xyz="0 1 0"/>
    	<origin rpy="0 0 0" xyz="0 0 0"/>
    </joint>
    <link name="arm_upper_right">
      <visual>
        <geometry>
          <cylinder length="0.08" radius="0.01"/>
        </geometry>
        <origin rpy="0 0 0" xyz="0 0 -0.03"/>
        <material name="white"/>
      </visual>
      <collision>
        <geometry>
          <cylinder length="0.08" radius="0.01"/>
        </geometry>
        <origin rpy="0 0 0" xyz="0 0 -0.03"/>
      </collision>
      <inertial>
        <mass value="0.006"/>
        <inertia ixx="0.001" ixy="0.0" ixz="0.0" iyy="0.001" iyz="0.0" izz="0.001"/>
      </inertial>
    </link>
    <joint name="arm_elbow_right_yaw" type="revolute">
  	<limit effort="1000.0" lower="-3.14" upper="3.14" velocity="0.5"/>
    	<parent link="arm_upper_right"/>
    	<child link="arm_elbow_right_joint"/>
  	<axis xyz="0 0 1"/>
    	<origin xrpy="0 0 0" xyz="0.00 0 -0.08"/>
    </joint>
    <link name="arm_elbow_right_joint">
    </link>
    <joint name="arm_elbow_right_roll" type="revolute">
  	<limit effort="1000.0" lower="-3.14" upper="3.14" velocity="0.5"/>
    	<parent link="arm_elbow_right_joint"/>
    	<child link="arm_lower_right"/>
    	<origin xrpy="0 0 0" xyz="0 0 0"/>
    </joint>
    <link name="arm_lower_right">
      <visual>
        <geometry>
          <cylinder length="0.08" radius="0.01"/>
        </geometry>
        <origin rpy="0 0 0" xyz="0 0 -0.03"/>
        <material name="gray"/>
      </visual>
      <collision>
        <geometry>
          <cylinder length="0.07" radius="0.01"/>
        </geometry>
        <origin rpy="0 0 0" xyz="0 0 -0.04"/>
      </collision>
      <inertial>
        <mass value="0.006"/>
        <inertia ixx="0.001" ixy="0.0" ixz="0.0" iyy="0.001" iyz="0.0" izz="0.001"/>
      </inertial>
    </link>
    <joint name="arm_wrist_right_yaw" type="revolute">
  	<limit effort="1000.0" lower="-3.14" upper="3.14" velocity="0.5"/>
    	<parent link="arm_lower_right"/>
  	<axis xyz="0 0 1"/>
    	<child link="arm_hand_right"/>
    	<origin xrpy="0 0 0" xyz="0.00 0 -0.08"/>
    </joint>
    <link name="arm_hand_right">
      <visual>
        <geometry>
          <box size="0.02 0.01 0.02"/>
        </geometry>
        <origin rpy="0 0 0" xyz="0 0 -0.01"/>
        <material name="red"/>
      </visual>
      <collision>
        <geometry>
          <box size="0.02 0.01 0.02"/>
        </geometry>
        <origin rpy="0 0 0" xyz="0 0 -0.01"/>
      </collision>
      <inertial>
        <mass value="0.006"/>
        <inertia ixx="0.001" ixy="0.0" ixz="0.0" iyy="0.001" iyz="0.0" izz="0.001"/>
      </inertial>
    </link>

  <joint name="arm_shoulder_left_roll" type="revolute">
	<limit effort="1000.0" lower="-0.4" upper="3.14" velocity="0.5"/>
  	<parent link="base_link"/>
 	<child link="arm_shoulder_left_joint"/>
  	<origin rpy="0 0.1 0" xyz="-0.045 0 0.07"/>
  </joint>
  <link name="arm_shoulder_left_joint">
  </link>
  <joint name="arm_shoulder_left_pitch" type="revolute">
	<limit effort="1000.0" lower="0" upper="3.14" velocity="0.5"/>
  	<parent link="arm_shoulder_left_joint"/>
 	<child link="arm_left_upper"/>
	<axis xyz="0 1 0"/>
  	<origin rpy="0 0 0" xyz="0 0 0"/>
  </joint>
  <link name="arm_left_upper">
    <visual>
      <geometry>
        <cylinder length="0.08" radius="0.01"/>
      </geometry>
      <origin rpy="0 0 0" xyz="0 0.0 -0.04"/>
      <material name="white"/>
    </visual>
    <collision>
      <geometry>
        <cylinder length="0.08" radius="0.01"/>
      </geometry>
      <origin rpy="0 0 0" xyz="0 0 -0.03"/>
    </collision>
    <inertial>
      <mass value="0.006"/>
      <inertia ixx="0.001" ixy="0.0" ixz="0.0" iyy="0.001" iyz="0.0" izz="0.001"/>
    </inertial>
  </link>
  <joint name="arm_elbow_left_yaw" type="revolute">
	<limit effort="1000.0" lower="-1.57" upper="1.57" velocity="0.5"/>
  	<parent link="arm_left_upper"/>
  	<child link="arm_elbow_left_joint"/>
	<axis xyz="0 0 1"/>
  	<origin xrpy="0 0 0" xyz="0 0 -0.10"/>
  </joint>
  <link name="arm_elbow_left_joint">
  </link>
  <joint name="arm_elbow_left_roll" type="revolute">
	<limit effort="1000.0" lower="0.0" upper="3.14" velocity="0.5"/>
  	<parent link="arm_elbow_left_joint"/>
  	<child link="arm_left_lower"/>
  	<origin xrpy="0 0 0" xyz="0 0 0"/>
  </joint>
  <link name="arm_left_lower">
    <visual>
      <geometry>
        <cylinder length="0.08" radius="0.01"/>
      </geometry>
      <origin rpy="0 0 0" xyz="0 0 -0.04"/>
      <material name="gray"/>
    </visual>
    <collision>
      <geometry>
        <cylinder length="0.08" radius="0.01"/>
      </geometry>
      <origin rpy="0 0 0" xyz="0 0 -0.04"/>
    </collision>
    <inertial>
      <mass value="0.006"/>
      <inertia ixx="0.001" ixy="0.0" ixz="0.0" iyy="0.001" iyz="0.0" izz="0.001"/>
    </inertial>
  </link>
  <joint name="arm_wrist_left_yaw" type="revolute">
	<limit effort="1000.0" lower="-3.14" upper="3.14" velocity="0.5"/>
  	<parent link="arm_left_lower"/>
	<axis xyz="0 0 1"/>
  	<child link="arm_hand_left"/>
  	<origin xrpy="0 0 0" xyz="0.00 0 -0.08"/>
  </joint>
  <link name="arm_hand_left">
    <visual>
      <geometry>
        <box size="0.02 0.01 0.02"/>
      </geometry>
      <origin rpy="0 0 0" xyz="0 0 -0.01"/>
      <material name="green"/>
    </visual>
    <collision>
      <geometry>
        <box size="0.02 0.01 0.02"/>
      </geometry>
      <origin rpy="0 0 0" xyz="0 0 -0.01"/>
    </collision>
    <inertial>
      <mass value="0.006"/>
      <inertia ixx="0.001" ixy="0.0" ixz="0.0" iyy="0.001" iyz="0.0" izz="0.001"/>
    </inertial>
  </link>



    <joint name="right_groin" type="fixed">
    	<parent link="base_link"/>
   	<child link="right_upper_leg"/>
    	<origin xyz="0.02 0 -0.11"/>
    </joint>
    <link name="right_upper_leg">
      <visual>
        <geometry>
          <cylinder length="0.08" radius="0.01"/>
        </geometry>
        <material name="white"/>
      </visual>
      <collision>
        <geometry>
          <cylinder length="0.08" radius="0.01"/>
        </geometry>
      </collision>
      <inertial>
        <mass value="0.006"/>
        <inertia ixx="0.001" ixy="0.0" ixz="0.0" iyy="0.001" iyz="0.0" izz="0.001"/>
      </inertial>
    </link>
    <joint name="knee_right" type="fixed">
    	<parent link="right_upper_leg"/>
    	<child link="right_lower_leg"/>
    	<origin xyz="0.00 0 -0.08"/>
    </joint>
    <link name="right_lower_leg">
      <visual>
        <geometry>
          <cylinder length="0.08" radius="0.01"/>
        </geometry>
        <material name="gray"/>
      </visual>
      <collision>
        <geometry>
          <cylinder length="0.08" radius="0.01"/>
        </geometry>
      </collision>
      <inertial>
        <mass value="0.006"/>
        <inertia ixx="0.001" ixy="0.0" ixz="0.0" iyy="0.001" iyz="0.0" izz="0.001"/>
      </inertial>
    </link>
    <joint name="right_ankle" type="fixed">
    	<parent link="right_lower_leg"/>
    	<child link="right_foot"/>
    	<origin xyz="0.00 0.015 -0.05"/>
    </joint>
    <link name="right_foot">
      <visual>
        <geometry>
          <box size="0.02 0.05 0.02"/>
        </geometry>
        <material name="red"/>
      </visual>
      <collision>
        <geometry>
          <box size="0.02 0.05 0.02"/>
        </geometry>
      </collision>
      <inertial>
        <mass value="0.006"/>
        <inertia ixx="0.001" ixy="0.0" ixz="0.0" iyy="0.001" iyz="0.0" izz="0.001"/>
      </inertial>
    </link>
    
    
    <joint name="left_groin" type="fixed">
    	<parent link="base_link"/>
   	<child link="left_upper_leg"/>
    	<origin xyz="-0.02 0 -0.11"/>
    </joint>
    <link name="left_upper_leg">
      <visual>
        <geometry>
          <cylinder length="0.08" radius="0.01"/>
        </geometry>
        <material name="white"/>
      </visual>
      <collision>
        <geometry>
          <cylinder length="0.08" radius="0.01"/>
        </geometry>
      </collision>
      <inertial>
        <mass value="0.006"/>
        <inertia ixx="0.001" ixy="0.0" ixz="0.0" iyy="0.001" iyz="0.0" izz="0.001"/>
      </inertial>
    </link>
    <joint name="knee_left" type="fixed">
    	<parent link="left_upper_leg"/>
    	<child link="left_lower_leg"/>
    	<origin xyz="0.00 0 -0.08"/>
    </joint>
    <link name="left_lower_leg">
      <visual>
        <geometry>
          <cylinder length="0.08" radius="0.01"/>
        </geometry>
        <material name="gray"/>
      </visual>
      <collision>
        <geometry>
          <cylinder length="0.08" radius="0.01"/>
        </geometry>
      </collision>
      <inertial>
        <mass value="0.006"/>
        <inertia ixx="0.001" ixy="0.0" ixz="0.0" iyy="0.001" iyz="0.0" izz="0.001"/>
      </inertial>
    </link>
    <joint name="left_ankle" type="fixed">
    	<parent link="left_lower_leg"/>
    	<child link="left_foot"/>
    	<origin xyz="0 0.015 -0.05"/>
    </joint>
    <link name="left_foot">
      <visual>
        <geometry>
          <box size="0.02 0.05 0.02"/>
        </geometry>
        <material name="green"/>
      </visual>
      <collision>
        <geometry>
          <box size="0.02 0.05 0.02"/>
        </geometry>
      </collision>
      <inertial>
        <mass value="0.006"/>
        <inertia ixx="0.001" ixy="0.0" ixz="0.0" iyy="0.001" iyz="0.0" izz="0.001"/>
      </inertial>
    </link>

  
  <transmission name="arm_shoulder_left_roll_tran">
    <type>transmission_interface/SimpleTransmission</type>
    <joint name="arm_shoulder_left_roll">
      <hardwareInterface>PositionJointInterface</hardwareInterface>
    </joint>
    <actuator name="arm_shoulder_left_roll_motor">
      <hardwareInterface>PositionJointInterface</hardwareInterface>
      <mechanicalReduction>1</mechanicalReduction>
    </actuator>
  </transmission>
	
  <transmission name="arm_shoulder_left_pitch_tran">
    <type>transmission_interface/SimpleTransmission</type>
    <joint name="arm_shoulder_left_pitch" >
      <hardwareInterface>PositionJointInterface</hardwareInterface>
    </joint>
    <actuator name="arm_shoulder_left_pitch_motor">
      <hardwareInterface>PositionJointInterface</hardwareInterface>
      <mechanicalReduction>1</mechanicalReduction>
    </actuator>
  </transmission>

  <transmission name="arm_elbow_left_yaw_tran">
    <type>transmission_interface/SimpleTransmission</type>
    <joint name="arm_elbow_left_yaw">
      <hardwareInterface>PositionJointInterface</hardwareInterface>
    </joint>
    <actuator name="arm_elbow_left_yaw_motor">
      <hardwareInterface>PositionJointInterface</hardwareInterface>
      <mechanicalReduction>1</mechanicalReduction>
    </actuator>
  </transmission>

  <transmission name="arm_elbow_left_roll_tran">
    <type>transmission_interface/SimpleTransmission</type>
    <joint name="arm_elbow_left_roll">
      <hardwareInterface>PositionJointInterface</hardwareInterface>
    </joint>
    <actuator name="arm_elbow_left_roll_motor">
      <hardwareInterface>PositionJointInterface</hardwareInterface>
      <mechanicalReduction>1</mechanicalReduction>
    </actuator>
  </transmission>

  <transmission name="arm_wrist_left_yaw_tran">
    <type>transmission_interface/SimpleTransmission</type>
    <joint name="arm_wrist_left_yaw">
      <hardwareInterface>PositionJointInterface</hardwareInterface>
    </joint>
    <actuator name="arm_wrist_left_yaw_motor">
      <hardwareInterface>PositionJointInterface</hardwareInterface>
      <mechanicalReduction>1</mechanicalReduction>
    </actuator>
  </transmission>
  <gazebo>
    <plugin name="gazebo_ros_control" filename="libgazebo_ros_control.so">
      <robotNamespace>/bluecrescent</robotNamespace>
    </plugin>
  </gazebo>
</robot>
